<?xml version="1.0" encoding="utf-8"?>
<robot name="robotbody" xmlns:xacro="http://www.ros.org/wiki/xacro">

  <xacro:include filename="$(find mbot_description)/urdf/common_properties.xacro"/>
    <xacro:include filename="$(find mbot_description)/urdf/robotbody.gazebo.xacro"/>
    <link name="base_footprint"/>

    <joint name="base_joint" type="fixed">
      <origin xyz="0 0 0.05" rpy="0 0 0" />
      <parent link="base_footprint"/>
      <child link="base_link" />
    </joint>
    
    <link name="base_link">
    <inertial>
      <origin
        xyz="0.249258895595124 3.73456791304785E-17 0.375401162790698" rpy="0 0 0" />
      <mass value="1.35088484104347E-05" />
      <inertia
        ixx="7.45408306911053E-11"
        ixy="1.07705808926163E-29"
        ixz="1.14794124923144E-27"
        iyy="6.18220928330484E-11"
        iyz="-3.30354170509237E-27"
        izz="1.10902933060689E-10" />
    </inertial>
    <visual>
      <origin xyz="0 0 0" rpy="0 0 0" />
      <geometry>
        <mesh filename="package://mbot_description/meshes/base_link.STL" />
      </geometry>
      <material name="light_black"/>
    </visual>
    <collision>
      <origin
        xyz="0 0 0"
        rpy="0 0 0" />
      <geometry>
        <mesh
          filename="package://mbot_description/meshes/base_link.STL" />
      </geometry>
    </collision>
  </link>
  <link name="Right_Wheel">
    <inertial>
      <origin xyz="0.22316 0.2449 0.041366" rpy="0 0 0" />
      <mass value="20.752" />
      <inertia
        ixx="1.4826"
        ixy="-0.000156"
        ixz="-0.10241"
        iyy="1.6106"
        iyz="-1.7706E-05"
        izz="2.7615" />
    </inertial>
    <visual>
      <origin xyz="0 0 0" rpy="0 0 0" />
      <geometry>
        <mesh filename="package://mbot_description/meshes/Right_Wheel.STL" />
      </geometry>
      <material name="blue"/>
    </visual>
    <collision>
      <origin xyz="0 0 0" rpy="0 0 0" />
      <geometry>
        <mesh filename="package://mbot_description/meshes/Right_Wheel.STL" />
      </geometry>
    </collision>
  </link>
  
  
  <joint name="Joint_Wheel_Right" type="continuous">
    <origin xyz="-0.0161690113816193 -0.244900000000001 0.0476619772367589" rpy="0 0 0" />
    <parent
      link="base_link" />
    <child
      link="Right_Wheel" />
    <axis xyz="0 -1 0" />
  </joint>
  
  
  <link name="Left_Wheel">
    <inertial>
      <origin xyz="0.22316 -0.2449 0.041366" rpy="0 0 0" />
      <mass value="20.752" />
      <inertia
        ixx="1.4826"
        ixy="-0.000156"
        ixz="-0.10241"
        iyy="1.6106"
        iyz="-1.7706E-05"
        izz="2.7615" />
    </inertial>
    <visual>
      <origin xyz="0 0 0" rpy="0 0 0" />
      <geometry>
        <mesh filename="package://mbot_description/meshes/Left_Wheel.STL" />
      </geometry>
      <material name="blue"/>
    </visual>
    <collision>
      <origin xyz="0 0 0" rpy="0 0 0" />
      <geometry>
        <mesh filename="package://mbot_description/meshes/Left_Wheel.STL" />
      </geometry>
    </collision>
  </link>
  
  
  <joint name="Joint_Wheel_Left" type="continuous">
    <origin xyz="-0.0161690113816188 0.2449 0.0476619772367578" rpy="0 0 0" />
    <parent link="base_link" />
    <child link="Left_Wheel" />
    <axis xyz="0 1 0" />
  </joint>
  
<!-- ***************************** Bucket *************************** -->  
  <link name="Bucket">
    <inertial>
      <origin xyz="-0.15184 -0.2117 0.041366" rpy="0 0 0" />
      <mass value="20.752" />
      <inertia
        ixx="1.4826"
        ixy="-0.000156"
        ixz="-0.10241"
        iyy="1.6106"
        iyz="-1.7706E-05"
        izz="2.7615" />
    </inertial>
    <visual>
      <origin xyz="0 0 0" rpy="0 0 0" />
      <geometry>
        <mesh filename="package://mbot_description/meshes/Bucket.STL" />
      </geometry>
      <material name="black"/>
    </visual>
    <collision>
      <origin xyz="0 0 0" rpy="0 0 0" />
      <geometry>
        <mesh filename="package://mbot_description/meshes/Bucket.STL" />
      </geometry>
    </collision>
  </link>
  
  
  <joint name="Joint_Bucket" type="fixed">
    <origin xyz="0.35883098861838 0.2117 0.0476619772367585" rpy="0 0 0" />
    <parent link="base_link" />
    <child link="Bucket" />
    <axis xyz="0 0 0" />
  </joint>
  
<!-- ************************** Camera ***********************-->
  <link name="Camera">
    <!-- <inertial>
      <origin xyz="-0.089339 0.00035055 -0.24797" rpy="0 0 0" />
      <mass value="1" />
      <inertia
        ixx="1.4826"
        ixy="-0.000156"
        ixz="-0.10241"
        iyy="1.6106"
        iyz="-1.7706E-05"
        izz="2.7615" />
    </inertial> -->
    <visual>
      <origin xyz="-0.089339 0.00035055 -0.24797" rpy="0 0 0" />
      <geometry>
        <mesh filename="package://mbot_description/meshes/Camera.STL" />
      </geometry>
      <material name="blue"/>
    </visual>
    <collision>
      <origin xyz="0 0 0" rpy="0 0 0" />
      <geometry>
        <mesh filename="package://mbot_description/meshes/Camera.STL" />
      </geometry>
    </collision>
  </link>
  
  <joint name="Joint_Camera" type="fixed">
    <origin xyz="0.296330988618383 -0.000352141499293662 0.336999999183837" rpy="0 0 0" />
    <parent link="base_link" />
    <child link="Camera" />
    <axis xyz="0 0 0" />
  </joint>
  
<!-- ******************************** Lidar ********************** -->
 <link name="Lidar">
    <inertial>
      <origin xyz="0 0 0" rpy="0 0 0" />
      <mass value="0.78508" />
      <inertia
        ixx="0.0011319"
        ixy="1.9576E-51"
        ixz="-2.7081E-36"
        iyy="0.0011319"
        iyz="2.5649E-19"
        izz="0.0019235" />
    </inertial>
    <visual>
      <origin xyz="-2.7756E-17 4.7455E-18 0.035" rpy="0 0 0" />
      <geometry>
        <mesh filename="package://mbot_description/meshes/sensors/lds.stl" scale="0.001 0.001 0.001"/>
      </geometry>
      <material name="blue"/>
    </visual>
    <collision>
      <origin xyz="0 0 0" rpy="0 0 0" />
      <geometry>
	 <cylinder length="0.0315" radius="0.055"/>
      </geometry>
    </collision>
  </link>
  
  <joint name="Joint_Lidar" type="fixed">
    <origin xyz="0.21533098861838 0 0.402999999999999" rpy="0 0 0" />
    <parent link="base_link" />
    <child link="Lidar" />
    <axis xyz="0 0 0" />
  </joint> 
  
<!--  ******************************* Passive Wheels ********************* -->
  <link name="Right_Front_Wheel">
    <inertial>
      <origin  xyz="-0.016839 0.2459 0.041366" rpy="0 0 0" />
      <mass value="2.752" />
      <inertia
        ixx="1.4826"
        ixy="-0.000156"
        ixz="-0.10241"
        iyy="1.6106"
        iyz="-1.7706E-05"
        izz="2.7615" />
    </inertial>
    <visual>
      <origin xyz="0 0 0" rpy="0 0 0" />
      <geometry>
        <mesh filename="package://mbot_description/meshes/Right_Front_Wheel.STL" />
      </geometry>
      <material name="light_black"/>
    </visual>
    <collision>
      <origin xyz="0 0 0" rpy="0 0 0" />
      <geometry>
        <mesh filename="package://mbot_description/meshes/Right_Front_Wheel.STL" />
      </geometry>
    </collision>
  </link>
  
  <joint name="Joint_Wheel_Front_Right" type="continuous">
    <origin xyz="0.223830988618383 -0.245900000000007 0.047661977236756" rpy="0 0 0" />
    <parent link="base_link" />
    <child link="Right_Front_Wheel" />
    <axis xyz="0 1 0" />
  </joint>
  
  
  <link name="Right_Back_Wheel">
    <inertial>
      <origin xyz="0.46316 0.246 0.041366" rpy="0 0 0" />
      <mass value="2.752" />
      <inertia
        ixx="1.4826"
        ixy="-0.000156"
        ixz="-0.10241"
        iyy="1.6106"
        iyz="-1.7706E-05"
        izz="2.7615" />
    </inertial>
    <visual>
      <origin xyz="0 0 0" rpy="0 0 0" />
      <geometry>
        <mesh filename="package://mbot_description/meshes/Right_Back_Wheel.STL" />
      </geometry>
      <material name="light_black"/>
    </visual>
    <collision>
      <origin xyz="0 0 0" rpy="0 0 0" />
      <geometry>
        <mesh filename="package://mbot_description/meshes/Right_Back_Wheel.STL" />
      </geometry>
    </collision>
  </link>
  
  <joint name="Joint_Wheel_Back_Right" type="continuous">
    <origin xyz="-0.256169011381623 -0.245999999999999 0.0476619772367576" rpy="0 0 0" />
    <parent link="base_link" />
    <child link="Right_Back_Wheel" />
    <axis xyz="0 1 0" />
  </joint>
  
  
  <link name="Left_Front_Wheel">
    <inertial>
      <origin xyz="-0.016839 -0.2459 0.041366" rpy="0 0 0" />
      <mass value="2.752" />
      <inertia
        ixx="1.4826"
        ixy="-0.000156"
        ixz="-0.10241"
        iyy="1.6106"
        iyz="-1.7706E-05"
        izz="2.7615" />
    </inertial>
    <visual>
      <origin xyz="0 0 0" rpy="0 0 0" />
      <geometry>
        <mesh filename="package://mbot_description/meshes/Left_Front_Wheel.STL" />
      </geometry>
      <material name="light_black"/>
    </visual>
    <collision>
      <origin xyz="0 0 0" rpy="0 0 0" />
      <geometry>
        <mesh filename="package://mbot_description/meshes/Left_Front_Wheel.STL" />
      </geometry>
    </collision>
  </link>
  
  <joint name="Joint_Wheel_Front_Left" type="continuous">
    <origin xyz="0.22383 0.2459 0.047662" rpy="0 0 0" />
    <parent link="base_link" />
    <child link="Left_Front_Wheel" />
    <axis xyz="0 -1 0" />
  </joint>
  
  
  <link name="Left_Back_Wheel">
    <inertial>
      <origin xyz="0.46316 -0.2459 0.041366" rpy="0 0 0" />
      <mass value="2.752" />
      <inertia
        ixx="1.4826"
        ixy="-0.000156"
        ixz="-0.10241"
        iyy="1.6106"
        iyz="-1.7706E-05"
        izz="2.7615" />
    </inertial>
    <visual>
      <origin xyz="0 0 0" rpy="0 0 0" />
      <geometry>
        <mesh filename="package://mbot_description/meshes/Left_Back_Wheel.STL" />
      </geometry>
      <material name="light_black"/>
    </visual>
    <collision>
      <origin xyz="0 0 0" rpy="0 0 0" />
      <geometry>
        <mesh filename="package://mbot_description/meshes/Left_Back_Wheel.STL" />
      </geometry>
    </collision>
  </link>
  
  <joint name="Joint_Wheel_Back_Left" type="continuous">
    <origin xyz="-0.25617 0.2459 0.047662" rpy="0 0 0" />
    <parent link="base_link" />
    <child link="Left_Back_Wheel" />
    <axis xyz="0 -1 0" />
  </joint>
</robot>
